   _____  _______      __  _____                            _            
  / ____|/ ____\ \    / / |_   _|                          | |           
 | |    | (___  \ \  / /    | |  _ __ ___  _ __   ___  _ __| |_ ___ _ __ 
 | |     \___ \  \ \/ /     | | | '_ ` _ \| '_ \ / _ \| '__| __/ _ \ '__|
 | |____ ____) |  \  /     _| |_| | | | | | |_) | (_) | |  | ||  __/ |   
  \_____|_____/    \/     |_____|_| |_| |_| .__/ \___/|_|   \__\___|_|   
                                          | |                         
                                          |_|

Connected, dropping old data for store 99
connected to database
importing data... please wait...

PROBLEMATIC FORMATTING IN FILE! --- line 1
BAD STATEMENT: INSERT INTO fromfiles (SKU, classCode, retailPrice, description, type, storeNumber) VALUES ("0000000000000000000101","101","0.0","NEW TEXTBOOKS     ","             R
","99");

{}
Traceback (most recent call last):
  File "/Users/Shared/RemoteShare/inventory/admin/csvImporter.py", line 101, in tryStatement
    cursor.execute(sqlStatement)
  File "/usr/local/lib/python3.9/site-packages/mysql/connector/cursor.py", line 551, in execute
    self._handle_result(self._connection.cmd_query(stmt))
  File "/usr/local/lib/python3.9/site-packages/mysql/connector/connection.py", line 490, in cmd_query
    result = self._handle_result(self._send_cmd(ServerCmd.QUERY, query))
  File "/usr/local/lib/python3.9/site-packages/mysql/connector/connection.py", line 395, in _handle_result
    raise errors.get_exception(packet)
mysql.connector.errors.ProgrammingError: 1146 (42S02): Table 'inventory.fromfiles' doesn't exist

During handling of the above exception, another exception occurred:

Traceback (most recent call last):
  File "/Users/Shared/RemoteShare/inventory/admin/csvImporter.py", line 162, in <module>
    numLines = parseIntoDB(filepath, storeNum)
  File "/Users/Shared/RemoteShare/inventory/admin/csvImporter.py", line 83, in parseIntoDB
    tryStatement(conn, statement, lineNum, str(storeNumber))
  File "/Users/Shared/RemoteShare/inventory/admin/csvImporter.py", line 110, in tryStatement
    infoDict[storeNum][2][lineNum] = sqlStatement
KeyError: '99'
